Workbook
Name Apersiapan1: 'A.1.1.Pekerjaan Persiapan'!$B$14:$I$14
Name Apersiapan10: 'A.1.1.Pekerjaan Persiapan'!$B$215:$I$215
Name Apersiapan11: 'A.1.1.Pekerjaan Persiapan'!$B$233:$I$233
Name Apersiapan12: 'A.1.1.Pekerjaan Persiapan'!$B$250:$I$250
Name Apersiapan13: 'A.1.1.Pekerjaan Persiapan'!$B$267:$I$267
Name Apersiapan14: 'A.1.1.Pekerjaan Persiapan'!$B$286:$I$286
Name Apersiapan15: 'A.1.1.Pekerjaan Persiapan'!$B$309:$I$309
Name Apersiapan16: 'A.1.1.Pekerjaan Persiapan'!$B$337:$I$337
Name Apersiapan2: 'A.1.1.Pekerjaan Persiapan'!$B$37:$I$37
Name Apersiapan3: 'A.1.1.Pekerjaan Persiapan'!$B$61:$I$61
Name Apersiapan4: 'A.1.1.Pekerjaan Persiapan'!$B$83:$I$83
Name Apersiapan5: 'A.1.1.Pekerjaan Persiapan'!$B$102:$I$102
Name Apersiapan6: 'A.1.1.Pekerjaan Persiapan'!$B$133:$I$133
Name Apersiapan7: 'A.1.1.Pekerjaan Persiapan'!$B$153:$I$153
Name Apersiapan8: 'A.1.1.Pekerjaan Persiapan'!$B$177:$I$177
Name Apersiapan9: 'A.1.1.Pekerjaan Persiapan'!$B$201:$I$201
Name BBongkaran1: 'A.1.2.Pekerjaan Bongkaran'!$B$3:$K$15
Name BBongkaran10: 'A.1.2.Pekerjaan Bongkaran'!$B$157:$I$174
Name BBongkaran11: 'A.1.2.Pekerjaan Bongkaran'!$B$176:$I$191
Name BBongkaran12: 'A.1.2.Pekerjaan Bongkaran'!$B$193:$I$208
Name BBongkaran13: 'A.1.2.Pekerjaan Bongkaran'!$B$210:$I$230
Name BBongkaran2: 'A.1.2.Pekerjaan Bongkaran'!$B$17:$J$33
Name BBongkaran3: 'A.1.2.Pekerjaan Bongkaran'!$B$35:$J$50
Name BBongkaran4: 'A.1.2.Pekerjaan Bongkaran'!$B$52:$J$68
Name BBongkaran5: 'A.1.2.Pekerjaan Bongkaran'!$B$70:$I$85
Name BBongkaran6: 'A.1.2.Pekerjaan Bongkaran'!$B$87:$I$102
Name BBongkaran7: 'A.1.2.Pekerjaan Bongkaran'!$B$104:$I$119
Name BBongkaran8: 'A.1.2.Pekerjaan Bongkaran'!$B$121:$I$138
Name BBongkaran9: 'A.1.2.Pekerjaan Bongkaran'!$B$140:$I$155
Name Bongkaran1: 'A.1.2.Pekerjaan Bongkaran'!$B$3:$I$15
Name CTanah1: 'A.1.3.Pekerjaan Tanah'!$B$3:$I$17
Name CTanah10: 'A.1.3.Pekerjaan Tanah'!$B$148:$I$162
Name CTanah11: 'A.1.3.Pekerjaan Tanah'!$B$164:$I$178
Name CTanah12: 'A.1.3.Pekerjaan Tanah'!$B$180:$I$198
Name CTanah13: 'A.1.3.Pekerjaan Tanah'!$B$200:$I$214
Name CTanah14: 'A.1.3.Pekerjaan Tanah'!$B$216:$I$230
Name CTanah15: 'A.1.3.Pekerjaan Tanah'!$B$232:$I$249
Name CTanah16: 'A.1.3.Pekerjaan Tanah'!$B$251:$I$266
Name CTanah17: 'A.1.3.Pekerjaan Tanah'!$B$268:$I$284
Name CTanah18: 'A.1.3.Pekerjaan Tanah'!$B$286:$I$303
Name CTanah2: 'A.1.3.Pekerjaan Tanah'!$B$20:$I$34
Name CTanah3: 'A.1.3.Pekerjaan Tanah'!$B$36:$I$50
Name CTanah4: 'A.1.3.Pekerjaan Tanah'!$B$53:$I$67
Name CTanah5: 'A.1.3.Pekerjaan Tanah'!$B$69:$I$83
Name CTanah6: 'A.1.3.Pekerjaan Tanah'!$B$85:$I$99
Name CTanah7: 'A.1.3.Pekerjaan Tanah'!$B$101:$I$115
Name CTanah8: 'A.1.3.Pekerjaan Tanah'!$B$117:$I$131
Name CTanah9: 'A.1.3.Pekerjaan Tanah'!$B$133:$I$146
Name DPondasi1: 'A.1.4.Pekerjaan Pondasi'!$B$4:$I$22
Name DPondasi10: 'A.1.4.Pekerjaan Pondasi'!$B$187:$I$208
Name DPondasi11: 'A.1.4.Pekerjaan Pondasi'!$B$210:$I$229
Name DPondasi2: 'A.1.4.Pekerjaan Pondasi'!$B$24:$I$43
Name DPondasi3: 'A.1.4.Pekerjaan Pondasi'!$B$45:$I$63
Name DPondasi4: 'A.1.4.Pekerjaan Pondasi'!$B$65:$I$83
Name DPondasi5: 'A.1.4.Pekerjaan Pondasi'!$B$85:$I$103
Name DPondasi6: 'A.1.4.Pekerjaan Pondasi'!$B$105:$I$124
Name DPondasi7: 'A.1.4.Pekerjaan Pondasi'!$B$126:$I$145
Name DPondasi8: 'A.1.4.Pekerjaan Pondasi'!$B$147:$I$166
Name DPondasi9: 'A.1.4.Pekerjaan Pondasi'!$B$168:$I$185
Name EDinding1: 'A.1.5.Pekerjaan Pasangan'!$B$4:$J$22

Sheet DAFTAR ISI
B7: A.1. AHSP KONSTRUKSI BIDANG CIPTA KARYA
B9: NO | C9: JENIS PEKERJAAN | D9: KODE
B10: A.1.1 | C10: PEKERJAAN PERSIAPAN
B11: A.1.1.1 | C11: (K3) Pembuatan 1 m2 pagar sementara dari kayu | D11: 28/2016
B12: A.1.1.2 | C12: (K3) Pembuatan 1 m2 pagar sementara dari seng gelombang | D12: 28/2016
B13: A.1.1.3 | C13: (K3) Pembuatan 1 m2 pagar sementara dari kawat duri | D13: 28/2016
B14: A.1.1.4 | C14: Pengukuran dan pemasangan 1 m2 Bouwplank | D14: 28/2016
B15: A.1.1.5 | C15: (K3) Pembuatan 1 m2 kantor sementara lantai plesteran | D15: 28/2016
B16: A.1.1.6 | C16: (K3) Pembuatan 1 m2 rumah jaga | D16: 28/2016
B17: A.1.1.7 | C17: (K3) Pembuatan 1 m2 gudang semen dan peralatan | D17: 28/2016
B18: A.1.1.8 | C18: (K3) Pembuatan 1 m2 bedeng pekerja | D18: 28/2016
B19: A.1.1.9 | C19: (K3) Pembersihan dan perataan lapangan 1 m2 | D19: 28/2016
B20: A.1.1.10 | C20: (K3) Pembuatan 1 m2 perancah dari bambu | D20: 28/2016
B21: A.1.1.11 | C21: Pembuatan 1 buah kotak adukan ukuran 40 cm x 50 cm x 25 cm | D21: 28/2016
B22: A.1.1.12 | C22: Pembuatan 1 m2 jalan sementara | D22: 28/2016
... B26: A.1.1.16 | C26: Pembuatan Papan Nama Proyek 80x120 cm (bahan flexi) | D26: AK
B27: A.1.2 | C27: PEKERJAAN BONGKARAN
B28: A.1.2.1 | C28: Pembongkaran 1 m3 beton bertulang | D28: 28/2016
B29: A.1.2.2 | C29: Pembongkaran 1 m2 dinding tembok | D29: 28/2016
B30: A.1.2.3 | C30: Pembongkaran pasangan batu kali 1 m3 | D30: AK
B31: A.1.2.4 | C31: Pembongkaran lantai tegel untuk dipergunakan lagi 1 m2 | D31: AK
B32: A.1.2.5 | C32: Mengupas plesteran lama 1 m2 | D32: AK
B33: A.1.2.6 | C33: Pembongkaran genteng / sirap untuk dipergunakan lagi 1 m2 | D33: AK
B34: A.1.2.7 | C34: Pembongkaran atap seng 1 m2 | D34: AK
B35: A.1.2.8 | C35: Pembongkaran usuk / reng dipakai lagi 1 m2 | D35: AK
B36: A.1.2.9 | C36: Pembongkaran usuk / reng tidak dipakai lagi 1 m2 | D36: AK
B37: A.1.2.10 | C37: Pembongkaran kayu balok loteng, kuda-kuda, dlurung, jembatan untuk digunakan lagi 1 m3 | D37: AK
B38: A.1.2.11 | C38: Pembongkaran kayu balok loteng, kuda-kuda, dlurung, jembatan tidak digunakan lagi 1 m3 | D38: AK
B39: A.1.2.12 | C39: Pembongkaran Plafon dgn rangka, tidak digunakan lagi 1 m2 | D39: AK
B40: A.1.2.13 | C40: Mengerjakan kembali bangunan kayu yang telah dibongkar 1 m3 | D40: AK
B41: A.1.3 | C41: PEKERJAAN TANAH
B42: A.1.3.1 | C42: Penggalian tanah biasa sedalam 1 m | D42: 28/2016
B43: A.1.3.2 | C43: Penggalian tanah biasa sedalam 2 m | D43: 28/2016
B44: A.1.3.3 | C44: Penggalian tanah biasa sedalam 3 m | D44: 28/2016
B45: A.1.3.4 | C45: Penggalian tanah keras sedalam 1 m | D45: 28/2016
B46: A.1.3.5 | C46: Penggalian tanah cadas sedalam 1 m | D46: 28/2016
B47: A.1.3.6 | C47: Penggalian tanah lumpur sedalam 1 m | D47: 28/2016
B48: A.1.3.7 | C48: Pengerjaan stripping setinggi 1 m | D48: 28/2016
B49: A.1.3.8 | C49: (K3) Pembuangan tanah | D49: 28/2016
B50: A.1.3.9 | C50: Pengurugan kembali 1 m3 galian tanah | D50: 28/2016
...

Sheet PERBANDINGAN
B7: A.1. AHSP KONSTRUKSI BIDANG CIPTA KARYA
B9: No. | C9: KELOMPOK PEKERJAAN | D9: No. | E9: AHSP
E10: PERWAL NO. 66 Tahun 2015 | G10: PERMEN PU NO.28/PRT/M/2016 | I10: PERMEN PU NO.11/PRT/M/2013
D11: A.1.1 PEKERJAAN PERSIAPAN
B12: 1 | C12: PEKERJAAN PERSIAPAN | D12: 1 | E12: Pekerjaan Pengukuran & Pemasangan Bowplank | F12: 4 | G12: Pengukuran dan pemasangan Bouwplank 1 m2 | H12: 4 | I12: Pengukuran dan pemasangan Bouwplank 1 m2
C13: A.1.1 | D13: =D12+1 -> 2 | E13: Pekerjaan Pengukuran Gedung 1 m2
D14: =D13+1 -> 3 | E14: Membersihkan Lapangan dan Perataan 1 m2 | F14: 8 | G14: (K3) Pembersihan dan perataan lapangan 1 m2 | H14: 8 | I14: Pembersihan dan perataan lapangan 1 m2
D15: =D14+1 -> 4 | E15: Pembuatan jalan sementara, tebal 25 cm per 1 m2
D16: =D15+1 -> 5 | E16: Pembuatan Jalan Sementara 1 m2 | F16: 12 | G16: Pembuatan 1 m2 jalan sementara | H16: 12 | I16: Pembuatan 1 m2 jalan sementara
D17: =D16+1 -> 6 | E17: Pekerjaan Kantor Direksi Keet , dengan lantai plesteran 1 m2 | F17: 5 | G17: Pembuatan 1 m2 kantor sementara | H17: 5 | I17: Pembuatan 1 m2 kantor sementara
D18: =D17+1 -> 7 | E18: Pagar Sementara dari Seng Gelombang tinggi 2 m | F18: 2 | G18: (K3) Pembuatan 1 m2 pagar sementara dari seng gelombang | H18: 2 | I18: Pembuatan 1 m2 pagar sementara dari seng gelombang
D19: =D18+1 -> 8 | E19: Pagar Sementara dari Kawat Duri tinggi 1.8 m | F19: 3 | G19: (K3) Pembuatan 1 m2 pagar sementara dari kawat duri | H19: 3 | I19: Pembuatan 1 m2 pagar sementara dari kawat duri
D20: =D19+1 -> 9 | E20: Pagar Sementara dari Kayu tinggi 2 m | F20: 1 | G20: (K3) Pembuatan 1 m2 pagar sementara dari kayu | H20: 1 | I20: Pembuatan 1 m2 pagar sementara dari kayu
D21: =D20+1 -> 10 | E21: Pasang pagar kawat jaring galvanis, tinggi 1,00 m | F21: 15 | G21: Pemasangan 1 m2 kawat jaring galvanis | H21: 15 | I21: Pemasangan 1 m2 kawat jaring galvanis
D22: =D21+1 -> 11 | E22: Pembuatan Gudang Semen dan Alat - alat 1 m2 | F22: 6 | G22: (K3) Pembuatan 1 m2 gudang | H22: 6 | I22: Pembuatan 1 m2 gudang
D23: =D22+1 -> 12 | E23: Pembuatan Rumah Jaga / Konstruksi Kayu 1 m2 | F23: 7 | G23: (K3) Pembuatan 1 m2 rumah jaga | H23: 7 | I23: Pembuatan 1 m2 rumah jaga
D24: =D23+1 -> 13 | E24: Pembuatan Bedeng Buruh 1 m2 | F24: 9 | G24: (K3) Pembuatan 1 m2 bedeng pekerja | H24: 9 | I24: Pembuatan 1 m2 bedeng pekerja
D25: =D24+1 -> 14 | E25: Pembuatan Bak Adukan ( 40 x 50 x 20 ) cm 1 m2 | F25: 10 | G25: Pembuatan 1 m2 bak adukan | H25: 10 | I25: Pembuatan 1 m2 bak adukan
D26: =D25+1 -> 15 | E26: Pembuatan Stegger dari Bambu, 1 m2 | F26: 11 | G26: (K3) Pembuatan 1 m2 perancah dari bambu | H26: 11 | I26: Pembuatan 1 m2 perancah dari bambu
D27: =D26+1 -> 16 | E27: Pasang pagar beton pracetak ( 5 x 50 x 213 ) cm | F27: 16 | G27: Pemasangan 1 m2 pagar beton pracetak 50x50x240 untuk pagar | H27: 16 | I27: Pemasangan 1 m2 pagar beton pracetak
D28: =D27+1 -> 17 | E28: Membuat Papan Nama Proyek 80x120 cm (bahan seng)
D29: =D28+1 -> 18 | E29: Membuat Papan Nama Proyek 80x120 cm (bahan flexi)
D30: =D29+1 -> 19 | E30: Pemasangan 1m2 pagar kawat jaring galvanis panjang 240 cm
D31: =D30+1 -> 20 | E31: Pembuatan 1 buah kotak adukan ukuran 40cm x50cm x25cm
B33: 2 | D33: A.1.2 PEKERJAAN BONGKARAN
C34: A.1.2 | D34: 1 | E34: Membongkar pasangan batu kali 1 m3
D35: =D34+1 -> 2 | E35: Membongkar pasangan batu merah dan membersihkan 1 m3
D36: =D35+1 -> 3 | E36: Pembongkaran 1m2 dinding tembok bata | F36: 14 | G36: Pembongkaran 1 m2 dinding tembok | H36: 14 | I36: Pembongkaran 1 m2 dinding tembok
D37: =D36+1 -> 4 | E37: Membongkar beton bertulang dan membersihkan 1 m3
D38: =D37+1 -> 5 | E38: Pembongkaran 1m3 beton bertulang | F38: 13 | G38: Pembongkaran 1 m3 beton bertulang | H38: 13 | I38: Pembongkaran 1 m3 beton bertulang
D39: =D38+1 -> 6 | E39: Pekerjaan bongkar lantai tegel untuk dipergunakan lagi 1 m2
D40: =D39+1 -> 7 | E40: Mengupas plesteran lama 1 m2
D41: =D40+1 -> 8 | E41: Membongkar genteng / sirap untuk dipergunakan lagi 1 m2
D42: =D41+1 -> 9 | E42: Membongkar atap seng 1 m2
D43: =D42+1 -> 10 | E43: Membongkar usuk / reng dipakai lagi 1 m2
D44: =D43+1 -> 11 | E44: Membongkar usuk / reng tidak dipakai lagi 1 m2
D45: =D44+1 -> 12 | E45: Membongkar kayu balok loteng, kuda-kuda, dlurung, jembatan untuk digunakan lagi 1 m3
D46: =D45+1 -> 13 | E46: Membongkar kayu balok loteng, kuda-kuda, dlurung, jembatan tidak digunakan lagi 1 m3
D47: =D46+1 -> 14 | E47: Membongkar Plafon dgn rangka, tidak digunakan lagi 1 m2
D48: =D47+1 -> 15 | E48: Mengerjakan kembali bangunan kayu yang telah dibongkar 1 m3
...

Sheet REKAP
B7: A.1. AHSP KONSTRUKSI BIDANG CIPTA KARYA
B9: No. | C9: KELOMPOK PEKERJAAN | D9: No. | E9: JENIS PEKERJAAN | F9: PERWAL NO. 72 TAHUN 2013 | H9: PERMEN PU NO. 11/PRT/M/2013 | I9: PERWAL NO. 2015 | J9: PERMEN PU NO.28/PRT/M/2016
B10: 1 | C10: PEKERJAAN PERSIAPAN | D10: 1 | E10: Pekerjaan Pengukuran & Pemasangan Bowplank | F10: Ö | H10: Ö | I10: Ö
C11: A.1.1 | D11: =D10+1 -> 2 | E11: Pekerjaan Pengukuran Gedung 1 m2 | F11: Ö | I11: Ö
D12: =D11+1 -> 3 | E12: Membersihkan Lapangan dan Perataan 1 m2 | F12: Ö | H12: Ö | I12: Ö
D13: =D12+1 -> 4 | E13: Pembuatan jalan sementara, tebal 25 cm per 1 m2 | F13: Ö | I13: Ö
D14: =D13+1 -> 5 | E14: Pembuatan Jalan Sementara 1 m2 | F14: Ö | H14: Ö | I14: Ö
D15: =D14+1 -> 6 | E15: Pekerjaan Kantor Direksi Keet , dengan lantai plesteran 1 m2 | F15: Ö | H15: Ö | I15: Ö
D16: =D15+1 -> 7 | E16: Pagar Sementara dari Seng Gelombang tinggi 2 m | F16: Ö | H16: Ö | I16: Ö
D17: =D16+1 -> 8 | E17: Pagar Sementara dari Kawat Duri tinggi 1.8 m | F17: Ö | H17: Ö | I17: Ö
D18: =D17+1 -> 9 | E18: Pagar Sementara dari Kayu tinggi 2 m | F18: Ö | H18: Ö | I18: Ö
D19: =D18+1 -> 10 | E19: Pasang pagar kawat jaring galvanis, tinggi 1,00 m | F19: Ö | I19: Ö
D20: =D19+1 -> 11 | E20: Pembuatan Gudang Semen dan Alat - alat 1 m2 | F20: Ö | H20: Ö | I20: Ö
D21: =D20+1 -> 12 | E21: Pembuatan Rumah Jaga / Konstruksi Kayu 1 m2 | F21: Ö | H21: Ö | I21: Ö
D22: =D21+1 -> 13 | E22: Pembuatan Bedeng Buruh 1 m2 | F22: Ö | H22: Ö | I22: Ö
D23: =D22+1 -> 14 | E23: Pembuatan Bak Adukan ( 40 x 50 x 20 ) cm 1 m2 | F23: Ö | I23: Ö
D24: =D23+1 -> 15 | E24: Pembuatan Stegger dari Bambu, 1 m2 | F24: Ö | H24: Ö | I24: Ö
D25: =D24+1 -> 16 | E25: Pasang pagar beton pracetak ( 5 x 50 x 213 ) cm | F25: Ö | H25: Ö | I25: Ö
D26: =D25+1 -> 17 | E26: Membuat Papan Nama Proyek 80x120 cm (bahan seng) | F26: Ö | I26: Ö
D27: =D26+1 -> 18 | E27: Membuat Papan Nama Proyek 80x120 cm (bahan flexi) | F27: Ö | I27: Ö
D28: =D27+1 -> 19 | E28: Pemasangan 1m2 pagar kawat jaring galvanis panjang 240 cm | H28: Ö
D29: =D28+1 -> 20 | E29: Pembuatan 1 buah kotak adukan ukuran 40cm x50cm x25cm | H29: Ö
B31: 2 | C31: PEKERJAAN BONGKARAN | D31: 1 | E31: Membongkar pasangan batu kali 1 m3 | F31: Ö | I31: Ö
C32: A.1.2 | D32: =D31+1 -> 2 | E32: Membongkar pasangan batu merah dan membersihkan 1 m3 | F32: Ö | I32: Ö
D33: =D32+1 -> 3 | E33: Pembongkaran 1m2 dinding tembok bata | H33: Ö
D34: =D33+1 -> 4 | E34: Membongkar beton bertulang dan membersihkan 1 m3 | F34: Ö | I34: Ö
D35: =D34+1 -> 5 | E35: Pembongkaran 1m3 beton bertulang | H35: Ö
D36: =D35+1 -> 6 | E36: Pekerjaan bongkar lantai tegel untuk dipergunakan lagi 1 m2 | F36: Ö | I36: Ö
D37: =D36+1 -> 7 | E37: Mengupas plesteran lama 1 m2 | F37: Ö | I37: Ö
D38: =D37+1 -> 8 | E38: Membongkar genteng / sirap untuk dipergunakan lagi 1 m2 | F38: Ö | I38: Ö
D39: =D38+1 -> 9 | E39: Membongkar atap seng 1 m2 | F39: Ö | I39: Ö
D40: =D39+1 -> 10 | E40: Membongkar usuk / reng dipakai lagi 1 m2 | F40: Ö | I40: Ö
D41: =D40+1 -> 11 | E41: Membongkar usuk / reng tidak dipakai lagi 1 m2 | F41: Ö | I41: Ö
D42: =D41+1 -> 12 | E42: Membongkar kayu balok loteng, kuda-kuda, dlurung, jembatan untuk digunakan lagi 1 m3 | F42: Ö | I42: Ö
D43: =D42+1 -> 13 | E43: Membongkar kayu balok loteng, kuda-kuda, dlurung, jembatan tidak digunakan lagi 1 m3 | F43: Ö | I43: Ö
D44: =D43+1 -> 14 | E44: Membongkar Plafon dgn rangka, tidak digunakan lagi 1 m2 | F44: Ö | I44: Ö
D45: =D44+1 -> 15 | E45: Mengerjakan kembali bangunan kayu yang telah dibongkar 1 m3 | F45: Ö | I45: Ö
B47: 3 | C47: PEKERJAAN TANAH | D47: 1 | E47: Menggali tanah biasa sedalam 1 meter 1 m3 | F47: Ö | H47: Ö | I47: Ö
C48: A.1.3 | D48: 2 | E48: Menggali tanah biasa sedalam 2 meter m3 | F48: Ö | H48: Ö | I48: Ö
D49: 3 | E49: Menggali tanah biasa sedalam 3 meter m3 | F49: Ö | H49: Ö | I49: Ö
...

Sheet A.1.1.Pekerjaan Persiapan
F2: LAMPIRAN PERATURAN WALIKOTA YOGYAKARTA
F3: NOMOR
F4: TENTANG ANALISA HARGA SATUAN PEKERJAAN
F5: KONSTRUKSI DAN JASA LAINNYA DI LINGKUNGAN
F6: PEMERINTAH KOTA YOGYAKARTA
B8: KOEFISIEN HARGA SATUAN PEKERJAAN KOSTRUKSI DAN JASA LAINNYA
B10: A. | C10: AHSP KONTRUKSI
B12: A.1.1 | C12: =REKAP!C10 -> PEKERJAAN PERSIAPAN
B14: 1 | D14: (K3) Pembuatan 1 m2 pagar sementara dari kayu tinggi 2 meter
C15: No | D15: Uraian | E15: Kode | F15: Satuan | G15: Koefisien | H15: Harga Satuan (Rp) | I15: Jumlah Harga (Rp)
C16: A | D16: TENAGA
C17: 1 | D17: Pekerja | E17: L.01 | F17: OH | G17: 0.4
C18: 2 | D18: Tukang kayu | E18: L.02 | F18: OH | G18: 0.2
C19: 3 | D19: Kepala tukang | E19: L.03 | F19: OH | G19: 0.02
C20: 4 | D20: Mandor | E20: L.04 | F20: OH | G20: 0.02
G21: JUMLAH TENAGA KERJA
C22: B | D22: BAHAN
C23: 1 | D23: Dolken Kayu  8-10/400 cm | F23: Batang | G23: 1250
C24: 2 | D24: Semen portland | F24: Kg | G24: 5000
C25: 3 | D25: Pasir beton | F25: m3 | G25: 0.005
C26: 4 | D26: Koral beton | F26: m3 | G26: 0.009
C27: 5 | D27: Kayu 5/7 | F27: m3 | G27: 0.072
C28: 6 | D28: Paku biasa 2” – 5” | F28: Kg | G28: 0.06
C29: 7 | D29: Residu | F29: Liter | G29: 0.4
G30: JUMLAH HARGA BAHAN
C31: C | D31: PERALATAN
G32: JUMLAH HARGA ALAT
C33: D | D33: Jumlah (A+B+C)
C34: E | D34: Overhead & Profit (Contoh 15 %) | G34: 15% x D (maksimum)
C35: F | D35: Harga Satuan Pekerjaan (D+E)
B37: 2 | D37: (K3) Pembuatan 1 m2 pagar sementara dari seng gelombang tinggi 2 meter
C38: No | D38: Uraian | E38: Kode | F38: Satuan | G38: Koefisien | H38: Harga Satuan (Rp) | I38: Jumlah Harga (Rp)
C39: A | D39: TENAGA
C40: 1 | D40: Pekerja | E40: L.01 | F40: OH | G40: 0.2
C41: 2 | D41: Tukang kayu | E41: L.02 | F41: OH | G41: 0.4
C42: 3 | D42: Kepala tukang | E42: L.03 | F42: OH | G42: 0.02
C43: 4 | D43: Mandor | E43: L.04 | F43: OH | G43: 0.02
G44: JUMLAH TENAGA KERJA
C45: B | D45: BAHAN
C46: 1 | D46: Dolken kayu  8-10/400 cm | F46: Batang | G46: 1.25
...

Sheet A.1.2.Pekerjaan Bongkaran
B2: A.1.2 | C2: =REKAP!C31 -> PEKERJAAN BONGKARAN
B3: 1 | C3: Pembongkaran 1 m3 beton bertulang
C4: No | D4: Uraian | E4: Kode | F4: Satuan | G4: Koefisien | H4: Harga Satuan (Rp) | I4: Jumlah Harga (Rp)
C5: A | D5: TENAGA
D6: Pekerja | E6: L.01 | F6: OH | G6: 13.334
D7: Mandor | E7: L.04 | F7: OH | G7: 0.666
G8: JUMLAH TENAGA KERJA
C9: B | D9: BAHAN
G10: JUMLAH HARGA BAHAN
C11: C | D11: PERALATAN
G12: JUMLAH HARGA ALAT
C13: D | D13: Jumlah (A+B+C)
C14: E | D14: Overhead & Profit (Contoh 15 %) | G14: 15% x D (maksimum)
C15: F | D15: Harga Satuan Pekerjaan (D+E)
B17: 2 | C17: Pembongkaran 1 m3 dinding tembok bata
C18: No | D18: Uraian | E18: Kode | F18: Satuan | G18: Koefisien | H18: Harga Satuan (Rp) | I18: Jumlah Harga (Rp)
C19: A | D19: TENAGA
D20: Pekerja | E20: L.01 | F20: OH | G20: 6.667
D21: Mandor | E21: L.04 | F21: OH | G21: 0.333
G22: JUMLAH TENAGA KERJA
C23: B | D23: BAHAN
G27: JUMLAH HARGA BAHAN
C28: C | D28: PERALATAN
G30: JUMLAH HARGA ALAT
C31: D | D31: Jumlah (A+B+C)
C32: E | D32: Overhead & Profit (Contoh 15 %) | G32: 15% x D (maksimum)
C33: F | D33: Harga Satuan Pekerjaan (D+E)
B35: 3 | C35: Pembongkaran pasangan batu kali 1 m3
C36: No | D36: Uraian | E36: Kode | F36: Satuan | G36: Koefisien | H36: Harga Satuan | I36: Jumlah
H37: (Rp) | I37: (Rp)
C38: A | D38: Tenaga
C39: 1 | D39: Pekerja | E39: L.01 | F39: oh | G39: 0.4 | I39: =G39*H39 -> 0
C40: =C39+1 -> 2 | D40: Tukang batu | E40: L.02 | F40: oh | G40: 4 | I40: =G40*H40 -> 0
C41: Jumlah Harga Tenaga Kerja | I41: =SUM(I38:I40) -> 0
C42: B | D42: Bahan
C43: 1 | I43: =G43*H43 -> 0
C44: Jumlah Harga Bahan | I44: =SUM(I42:I43) -> 0
C45: C | D45: Peralatan
I46: =G46*H46 -> 0
C47: Jumlah Harga Peralatan | I47: =SUM(I45:I46) -> 0
...

Sheet A.1.3.Pekerjaan Tanah
B2: A.1.3 | C2: =REKAP!C47 -> PEKERJAAN TANAH
B3: 1 | C3: Penggalian 1 m3 tanah biasa sedalam 1 m
C4: No | D4: Uraian | E4: Kode | F4: Satuan | G4: Koefisien | H4: Harga Satuan (Rp) | I4: Jumlah Harga (Rp)
C5: A | D5: TENAGA
D6: Pekerja | E6: L.01 | F6: OH | G6: 0.75
D7: Mandor | E7: L.04 | F7: OH | G7: 0.025
G8: JUMLAH TENAGA KERJA
C9: B | D9: BAHAN
G11: JUMLAH HARGA BAHAN
C12: C | D12: PERALATAN
G14: JUMLAH HARGA ALAT
C15: D | D15: Jumlah (A+B+C)
C16: E | D16: Overhead & Profit (Contoh 15 %) | G16: 15% x D (maksimum)
C17: F | D17: Harga Satuan Pekerjaan (D+E)
B20: 2 | C20: Penggalian 1 m3 tanah biasa sedalam 2 m
C21: No | D21: Uraian | E21: Kode | F21: Satuan | G21: Koefisien | H21: Harga Satuan (Rp) | I21: Jumlah Harga (Rp)
C22: A | D22: TENAGA
D23: Pekerja | E23: L.01 | F23: OH | G23: 0.9
D24: Mandor | E24: L.04 | F24: OH | G24: 0.045
G25: JUMLAH TENAGA KERJA
C26: B | D26: BAHAN
G28: JUMLAH HARGA BAHAN
C29: C | D29: PERALATAN
G31: JUMLAH HARGA ALAT
C32: D | D32: Jumlah (A+B+C)
C33: E | D33: Overhead & Profit (Contoh 15%) | G33: 15% x D (maksimum)
C34: F | D34: Harga Satuan Pekerjaan (D+E)
B36: 3 | C36: Menggali 1 m3 tanah biasa sedalam 3 m
C37: No | D37: Uraian | E37: Kode | F37: Satuan | G37: Koefisien | H37: Harga Satuan (Rp) | I37: Jumlah Harga (Rp)
C38: A | D38: TENAGA
D39: Pekerja | E39: L.01 | F39: OH | G39: 1.05
D40: Mandor | E40: L.04 | F40: OH | G40: 0.067
G41: JUMLAH TENAGA KERJA
C42: B | D42: BAHAN
G44: JUMLAH HARGA BAHAN
C45: C | D45: PERALATAN
G47: JUMLAH HARGA ALAT
C48: D | D48: Jumlah (A+B+C)
C49: E | D49: Overhead & Profit (Contoh 15 %) | G49: 15% x D (maksimum)
C50: F | D50: Harga Satuan Pekerjaan (D+E)
...

Sheet A.1.4.Pekerjaan Pondasi
B2: A.1.4 | C2: ='[1]Lamp_1 (Konstruksi 1-199)'!$D$393 -> PEKERJAAN PONDASI
B4: 1 | C4: Pemasangan 1 m3 pondasi batu belah campuran 1SP : 3PP
C5: No | D5: Uraian | E5: Kode | F5: Satuan | G5: Koefisien | H5: Harga Satuan (Rp) | I5: Jumlah Harga (Rp)
C6: A | D6: TENAGA
D7: Pekerja | E7: L.01 | F7: OH | G7: 1.5
D8: Tukang batu | E8: L.02 | F8: OH | G8: 0.75
D9: Kepala tukang | E9: L.03 | F9: OH | G9: 0.075
D10: Mandor | E10: L.04 | F10: OH | G10: 0.075
G11: JUMLAH TENAGA KERJA
C12: B | D12: BAHAN
D13: Batu belah | F13: m3 | G13: 1.2
D14: Semen Portland | F14: Kg | G14: 202
D15: Pasir pasang | F15: m3 | G15: 0.485
G16: JUMLAH HARGA BAHAN
C17: C | D17: PERALATAN
G19: JUMLAH HARGA ALAT
C20: D | D20: Jumlah (A+B+C)
C21: E | D21: Overhead & Profit (Contoh 15 %) | G21: 15% x D (maksimum)
C22: F | D22: Harga Satuan Pekerjaan (D+E)
B24: 2 | C24: Pemasangan 1 m3 pondasi batu belah campuran 1SP : 4PP
C25: No | D25: Uraian | E25: Kode | F25: Satuan | G25: Koefisien | H25: Harga Satuan (Rp) | I25: Jumlah Harga (Rp)
C26: A | D26: TENAGA
D27: Pekerja | E27: L.01 | F27: OH | G27: 1.5
D28: Tukang batu | E28: L.02 | F28: OH | G28: 0.75
D29: Kepala tukang | E29: L.03 | F29: OH | G29: 0.075
D30: Mandor | E30: L.04 | F30: OH | G30: 0.075
G31: JUMLAH TENAGA KERJA
C32: B | D32: BAHAN
D33: Batu belah | F33: m3 | G33: 1.2
D34: Semen Portland | F34: Kg | G34: 163
D35: Pasir pasang | F35: m3 | G35: 0.52
G36: JUMLAH HARGA BAHAN
C37: C | D37: PERALATAN
G40: JUMLAH HARGA ALAT
C41: D | D41: Jumlah (A+B+C)
C42: E | D42: Overhead & Profit (Contoh 15 %) | G42: 15% x D (maksimum)
C43: F | D43: Harga Satuan Pekerjaan (D+E)
B45: 3 | C45: Pemasangan 1 m3 pondasi batu belah campuran 1SP : 5PP
C46: No | D46: Uraian | E46: Kode | F46: Satuan | G46: Koefisien | H46: Harga Satuan (Rp) | I46: Jumlah Harga (Rp)
C47: A | D47: TENAGA
...

Sheet A.1.5.Pekerjaan Pasangan
B2: A.1.5 | C2: ='[1]Lamp_1 (Konstruksi 1-199)'!$D$531 -> PEKERJAAN DINDING
B4: 1 | C4: Pemasangan 1m2 dinding bata merah (5x11x22) cm tebal 1 batu campuran 1SP : 2PP
C5: No | D5: Uraian | E5: Kode | F5: Satuan | G5: Koefisien | H5: Harga Satuan (Rp) | I5: Jumlah Harga (Rp)
C6: A | D6: TENAGA
D7: Pekerja | E7: L.01 | F7: OH | G7: 0.6
D8: Tukang batu | E8: L.02 | F8: OH | G8: 0.2
D9: Kepala tukang | E9: L.03 | F9: OH | G9: 0.02
D10: Mandor | E10: L.04 | F10: OH | G10: 0.03
G11: JUMLAH TENAGA KERJA
C12: B | D12: BAHAN
D13: Bata merah | F13: buah | G13: 140
D14: Semen Portland | F14: Kg | G14: 43.5
D15: Pasir pasang | F15: m3 | G15: 0.08
G16: JUMLAH HARGA BAHAN
C17: C | D17: PERALATAN
G19: JUMLAH HARGA ALAT
C20: D | D20: Jumlah (A+B+C)
C21: E | D21: Overhead & Profit (Contoh 15%) | G21: 15% x D (maksimum)
C22: F | D22: Harga Satuan Pekerjaan (D+E)
B24: 2 | C24: Pemasangan 1m2 dinding bata merah (5x11x22) cm tebal 1 batu campuran 1SP : 3PP
C25: No | D25: Uraian | E25: Kode | F25: Satuan | G25: Koefisien | H25: Harga Satuan (Rp) | I25: Jumlah Harga (Rp)
C26: A | D26: TENAGA
D27: Pekerja | E27: L.01 | F27: OH | G27: 0.6
D28: Tukang batu | E28: L.02 | F28: OH | G28: 0.2
D29: Kepala tukang | E29: L.03 | F29: OH | G29: 0.02
D30: Mandor | E30: L.04 | F30: OH | G30: 0.03
G31: JUMLAH TENAGA KERJA
C32: B | D32: BAHAN
D33: Bata merah | F33: buah | G33: 140
D34: Semen Portland | F34: Kg | G34: 32.95
D35: Pasir pasang | F35: m3 | G35: 0.091
G36: JUMLAH HARGA BAHAN
C37: C | D37: PERALATAN
G39: JUMLAH HARGA ALAT
C40: D | D40: Jumlah (A+B+C)
C41: E | D41: Overhead & Profit (Contoh 15%) | G41: 15% x D (maksimum)
C42: F | D42: Harga Satuan Pekerjaan (D+E)
B44: 3 | C44: Pemasangan 1m2 dinding bata merah (5x11x22) cm tebal 1 batu campuran 1SP : 4PP
C45: No | D45: Uraian | E45: Kode | F45: Satuan | G45: Koefisien | H45: Harga Satuan (Rp) | I45: Jumlah Harga (Rp)
C46: A | D46: TENAGA
...

Sheet A.1.6.Pekerjaan Beton
B2: A.1.6 | C2: ='[1]Lamp_1 (Konstruksi 1-199)'!$D$815 -> PEKERJAAN BETON
B4: 1 | C4: Membuat 1 m3 beton mutu f’c = 7,4 MPa
C5: No | D5: Uraian | E5: Kode | F5: Satuan | G5: Koefisien | H5: Harga Satuan (Rp) | I5: Jumlah Harga (Rp)
C6: A | D6: TENAGA
D7: Pekerja | E7: L.01 | F7: OH | G7: 1.65
D8: Tukang batu | E8: L.02 | F8: OH | G8: 0.275
D9: Kepala tukang | E9: L.03 | F9: OH | G9: 0.028
D10: Mandor | E10: L.04 | F10: OH | G10: 0.083
G11: JUMLAH TENAGA KERJA
C12: B | D12: BAHAN
D13: Semen Portland | F13: kg | G13: 247
D14: Pasir beton | F14: kg | G14: 869
D15: Kerikil (Maks 30 mm) | F15: kg | G15: 999
D16: Air | F16: Liter | G16: 215
G17: JUMLAH HARGA BAHAN
C18: C | D18: PERALATAN
G20: JUMLAH HARGA ALAT
C21: D | D21: Jumlah (A+B+C)
C22: E | D22: Overhead & Profit (Contoh 15 %) | G22: 15% x D (maksimum)
C23: F | D23: Harga Satuan Pekerjaan (D+E)
B25: 2 | C25: Membuat 1 m3 beton mutu f’c = 9,8 MPa
C26: No | D26: Uraian | E26: Kode | F26: Satuan | G26: Koefisien | H26: Harga Satuan (Rp) | I26: Jumlah Harga (Rp)
C27: A | D27: TENAGA
D28: Pekerja | E28: L.01 | F28: OH | G28: 1.65
D29: Tukang batu | E29: L.02 | F29: OH | G29: 0.275
D30: Kepala tukang | E30: L.03 | F30: OH | G30: 0.028
D31: Mandor | E31: L.04 | F31: OH | G31: 0.083
G32: JUMLAH TENAGA KERJA
C33: B | D33: BAHAN
D34: Semen Portland | F34: kg | G34: 276
D35: Pasir beton | F35: kg | G35: 828
D36: Kerikil (Maks 30mm) | F36: kg | G36: 1012
D37: Air | F37: Liter | G37: 215
G38: JUMLAH HARGA BAHAN
C39: C | D39: PERALATAN
G41: JUMLAH HARGA ALAT
C42: D | D42: Jumlah (A+B+C)
C43: E | D43: Overhead & Profit (Contoh 15 %) | G43: 15% x D (maksimum)
C44: F | D44: Harga Satuan Pekerjaan (D+E)
B46: 3 | C46: Membuat 1 m3 beton mutu f’c = 12,2 MPa
...

Sheet A.1.7.Beton Pracetak
B1: A.1.7 HARGA SATUAN PEKERJAAN BETON PRACETAK
C2: Untuk produksi pracetak bisa dilakukan dipabrik (cor di plant) atau di lapangan (cast in
C3: place). Indeks yang ada dalam pedoman ini hanya untuk pekerjaan produksi yang dilakukan di lapangan, terutama untuk analisa cetakan (bekisting) pracetak baik untuk komponen kolom, balok dan pelat.
B4: 1 | C4: (K3) Pembuatan 1 m2 lahan produksi tebal 8 cm beton f’c 14,5 MPa, slump (120 ± 20) mm
C5: No | D5: Uraian | E5: Kode | F5: Satuan | G5: Koefisien | H5: Harga Satuan (Rp) | I5: Jumlah Harga (Rp)
C6: A | D6: TENAGA
D7: Pekerja | E7: L.01 | F7: OH | G7: 0.132
D8: Tukang batu | E8: L.02 | F8: OH | G8: 0.022
D9: Kepala tukang | E9: L.03 | F9: OH | G9: 0.002
D10: Mandor | E10: L.04 | F10: OH | G10: 0.007
G11: JUMLAH TENAGA KERJA
C12: B | D12: BAHAN
D13: Semen PC | F13: Kg | G13: 26.08
D14: Pasir beton | F14: Kg | G14: 60.8
D15: Kerikil (maks 30 mm) | F15: Kg | G15: 82.32
D16: Air | F16: L | G16: 17.2
G17: JUMLAH HARGA BAHAN
C18: C | D18: PERALATAN
G20: JUMLAH HARGA ALAT
C21: D | D21: Jumlah (A+B+C)
C22: E | D22: Overhead & Profit (Contoh 15%) | G22: 15% x D (maksimum)
C23: F | D23: Harga Satuan Pekerjaan (D+E)
B25: 2 | C25: (K3) Pembuatan 1 m2 lahan produksi tebal 10 cm beton f’c 14,5 MPa, slump (120 ± 20) mm
C26: No | D26: Uraian | E26: Kode | F26: Satuan | G26: Koefisien | H26: Harga Satuan (Rp) | I26: Jumlah Harga (Rp)
C27: A | D27: TENAGA
D28: Pekerja | E28: L.01 | F28: OH | G28: 0.165
D29: Tukang batu | E29: L.02 | F29: OH | G29: 0.028
D30: Kepala tukang | E30: L.03 | F30: OH | G30: 0.003
D31: Mandor | E31: L.04 | F31: OH | G31: 0.008
G32: JUMLAH TENAGA KERJA
C33: B | D33: BAHAN
D34: Semen PC | F34: Kg | G34: 32.6
D35: Pasir beton | F35: Kg | G35: 76
D36: Kerikil (maks 30mm) | F36: Kg | G36: 102.9
D37: Air | F37: L | G37: 21.5
G38: JUMLAH HARGA BAHAN
C39: C | D39: PERALATAN
G41: JUMLAH HARGA ALAT
C42: D | D42: Jumlah (A+B+C)
C43: E | D43: Overhead & Profit (Contoh 15%) | G43: 15% x D (maksimum)
...

Sheet A.1.8.Pekerjaan Plesteran
B1: A.1.8 | C1: ='[1]Lamp_1 (Konstruksi 1-199)'!$D$1432 -> PEKERJAAN PLESTERAN
B2: 1 | C2: Pemasangan 1 m2 plesteran 1SP : 1PP tebal 15 mm
C3: No | D3: Uraian | E3: Kode | F3: Satuan | G3: Koefisien | H3: Harga Satuan (Rp) | I3: Jumlah Harga (Rp)
C4: A | D4: TENAGA
D5: Pekerja | E5: L.01 | F5: OH | G5: 0.3
D6: Tukang batu | E6: L.03 | F6: OH | G6: 0.15
D7: Kepala tukang | E7: L.03 | F7: OH | G7: 0.015
D8: Mandor | E8: L.04 | F8: OH | G8: 0.015
G9: JUMLAH TENAGA KERJA
C10: B | D10: BAHAN
D11: PC | F11: Kg | G11: 15.504
D12: PP | F12: m3 | G12: 0.016
G13: JUMLAH HARGA BAHAN
C14: C | D14: PERALATAN
G16: JUMLAH HARGA ALAT
C17: D | D17: Jumlah (A+B+C)
C18: E | D18: Overhead & Profit (Contoh 15%) | G18: 15% x D (maksimum)
C19: F | D19: Harga Satuan Pekerjaan (D+E)
B21: 2 | C21: Pemasangan 1 m2 plesteran 1SP : 2PP tebal 15 mm
C22: No | D22: Uraian | E22: Kode | F22: Satuan | G22: Koefisien | H22: Harga Satuan (Rp) | I22: Jumlah Harga (Rp)
C23: A | D23: TENAGA
D24: Pekerja | E24: L.01 | F24: OH | G24: 0.3
D25: Tukang batu | E25: L.03 | F25: OH | G25: 0.15
D26: Kepala tukang | E26: L.03 | F26: OH | G26: 0.015
D27: Mandor | E27: L.04 | F27: OH | G27: 0.015
G28: JUMLAH TENAGA KERJA
C29: B | D29: BAHAN
D30: PC | F30: Kg | G30: 10.224
D31: PP | F31: m3 | G31: 0.02
G32: JUMLAH HARGA BAHAN
C33: C | D33: PERALATAN
G35: JUMLAH HARGA ALAT
C36: D | D36: Jumlah (A+B+C)
C37: E | D37: Overhead & Profit (Contoh 15%) | G37: 15% x D (maksimum)
C38: F | D38: Harga Satuan Pekerjaan (D+E)
B40: 3 | C40: Pemasangan 1 m2 plesteran 1SP : 3PP tebal 15mm
C41: No | D41: Uraian | E41: Kode | F41: Satuan | G41: Koefisien | H41: Harga Satuan (Rp) | I41: Jumlah Harga (Rp)
C42: A | D42: TENAGA
D43: Pekerja | E43: L.01 | F43: OH | G43: 0.3
D44: Tukang batu | E44: L.03 | F44: OH | G44: 0.15
...

Sheet A.1.9.Pek Penutup Dinding
B2: A.1.9 | C2: ='[1]Lamp_1 (Konstruksi 1-199)'!$D$1703 -> PEKERJAAN PENUTUP LANTAI DAN DINDING
B4: 1 | C4: Pemasangan 1 m2 lantai ubin PC abu-abu ukuran 40cm x 40 cm
C5: No | D5: Uraian | E5: Kode | F5: Satuan | G5: Koefisien | H5: Harga Satuan (Rp) | I5: Jumlah Harga (Rp)
C6: A | D6: TENAGA
D7: Pekerja | E7: L.01 | F7: OH | G7: 0.25
D8: Tukang atu | E8: L.02 | F8: OH | G8: 0.125
D9: Kepala tukang | E9: L.03 | F9: OH | G9: 0.013
D10: Mandor | E10: L.04 | F10: OH | G10: 0.013
G11: JUMLAH TENAGA KERJA
C12: B | D12: BAHAN
D13: Ubin abu-abu | F13: buah | G13: 6.63
D14: Semen Portland | F14: kg | G14: 9.8
D15: Pasir pasang | F15: M3 | G15: 0.045
G16: JUMLAH HARGA BAHAN
C17: C | D17: PERALATAN
G19: JUMLAH HARGA ALAT
C20: D | D20: Jumlah (A+B+C)
C21: E | D21: Overhead & Profit (Contoh 15%) | G21: 15% x D (maksimum)
C22: F | D22: Harga Satuan Pekerjaan (D+E)
B24: 2 | C24: Pemasangan 1 m2 lantai ubin PC abu-abu ukuran 30 cm x30 cm
C25: No | D25: Uraian | E25: Kode | F25: Satuan | G25: Koefisien | H25: Harga Satuan (Rp) | I25: Jumlah Harga (Rp)
C26: A | D26: TENAGA
D27: Pekerja | E27: L.01 | F27: OH | G27: 0.25
D28: Tukang batu | E28: L.02 | F28: OH | G28: 0.125
D29: Kepala tukang | E29: L.03 | F29: OH | G29: 0.013
D30: Mandor | E30: L.04 | F30: OH | G30: 0.013
G31: JUMLAH TENAGA KERJA
C32: B | D32: BAHAN
D33: Ubin abu-abu | F33: Bh | G33: 11.87
D34: Semen Portland | F34: kg | G34: 10
D35: Pasir pasang | F35: M3 | G35: 0.045
G36: JUMLAH HARGA BAHAN
C37: C | D37: PERALATAN
G39: JUMLAH HARGA ALAT
C40: D | D40: Jumlah (A+B+C)
C41: E | D41: Overhead & Profit (Contoh 15%) | G41: 15% x D (maksimum)
C42: F | D42: Harga Satuan Pekerjaan (D+E)
B44: 3 | C44: Pemasangan 1 m2 lantai ubin PC abu-abu ukuran 20 cm x 20 cm
C45: No | D45: Uraian | E45: Kode | F45: Satuan | G45: Koefisien | H45: Harga Satuan (Rp) | I45: Jumlah Harga (Rp)
C46: A | D46: TENAGA
...

Sheet A.1.10.Pek Konblok
B2: A.1.10 | C2: =REKAP!C283 -> PEKERJAAN CONBLOCK
B3: 1 | C3: Pemasangan 1 m2 paving block natural tebal 6 cm
C4: No | D4: Uraian | E4: Kode | F4: Satuan | G4: Koefisien | H4: Harga Satuan (Rp) | I4: Jumlah Harga (Rp)
C5: A | D5: TENAGA
D6: Pekerja | E6: L.01 | F6: OH | G6: 0.25
D7: Tukang batu | E7: L.02 | F7: OH | G7: 0.5
D8: Kepala tukang | E8: L.03 | F8: OH | G8: 0.05
D9: Mandor | E9: L.04 | F9: OH | G9: 0.0013
G10: JUMLAH TENAGA KERJA
C11: B | D11: BAHAN
D12: Paving block 6 cm | F12: M2 | G12: 1.01
D13: Pasir beton | F13: M3 | G13: 0.05
G14: JUMLAH HARGA BAHAN
C15: C | D15: PERALATAN
D16: Peralatan | F16: % | G16: 10
G17: JUMLAH HARGA ALAT
C18: D | D18: Jumlah (A+B+C)
C19: E | D19: Overhead & Profit (Contoh 15%) | G19: 15% x D (maksimum)
B21: 2 | C21: Pemasangan 1 m2 paving block natural tebal 8 cm
C22: No | D22: Uraian | E22: Kode | F22: Satuan | G22: Koefisien | H22: Harga Satuan (Rp) | I22: Jumlah Harga (Rp)
C23: A | D23: TENAGA
D24: Pekerja | E24: L.01 | F24: OH | G24: 0.5
D25: Tukang batu | E25: L.02 | F25: OH | G25: 0.5
D26: Kepala tukang | E26: L.03 | F26: OH | G26: 0.05
D27: Mandor | E27: L.04 | F27: OH | G27: 0.0013
G28: JUMLAH TENAGA KERJA
C29: B | D29: BAHAN
D30: Paving block 8 cm natural | F30: M2 | G30: 1.01
D31: Pasir beton | F31: M3 | G31: =G13 -> 0.05
G32: JUMLAH HARGA BAHAN
C33: C | D33: PERALATAN
D34: Peralatan | F34: % | G34: 10
G35: JUMLAH HARGA ALAT
C36: D | D36: Jumlah (A+B+C)
C37: E | D37: Overhead & Profit (Contoh 15%) | G37: 15% x D (maksimum)
B39: 3 | C39: Pemasangan 1 m2 paving block berwarna tebal 6 cm
C40: No | D40: Uraian | E40: Kode | F40: Satuan | G40: Koefisien | H40: Harga Satuan (Rp) | I40: Jumlah Harga (Rp)
C41: A | D41: TENAGA
D42: Pekerja | E42: L.01 | F42: OH | G42: 0.25
D43: Tukang batu | E43: L.02 | F43: OH | G43: 0.5
...

Sheet TENAGA
C4: DAFTAR HARGA SATUAN TENAGA KERJA
C6: No | D6: Tenaga Kerja | E6: Kode | F6: Satuan | G6: Harga Satuan
G7: ( Rp. )
C8: 1 | D8: Pekerja | E8: L.01 | F8: Oh | G8: 0
C9: 2 | D9: Tukang | E9: L.02 | F9: Oh | G9: 0
D10: Tukang gali | E10: L.02 | F10: Oh | G10: 0
D11: Tukang batu/ tembok | E11: L.02 | F11: Oh | G11: 0
D12: Tukang kayu | E12: L.02 | F12: Oh | G12: 0
D13: Tukang besi/ besi beton | E13: L.02 | F13: Oh | G13: 0
D14: Tukang cat/ politur | E14: L.02 | F14: Oh | G14: 0
D15: Tukang pipa/ operator pompa | E15: L.02 | F15: Oh | G15: 0
D16: Tukang penganyam bronjong | E16: L.02 | F16: Oh | G16: 0
D17: Tukang tebas | E17: L.02 | F17: Oh | G17: 0
D18: Tukang las | E18: L.02 | F18: Oh | G18: 0
C19: 3 | D19: Kepala tukang | E19: L.03 | F19: Oh | G19: 0
C20: 4 | D20: Mandor | E20: L.04 | F20: Oh | G20: 0
C21: 5 | D21: Juru ukur | E21: L.05 | F21: Oh | G21: 0
C22: 6 | D22: Pembantu juru ukur | E22: L.06 | F22: Oh | G22: 0
C23: 7 | D23: Ahli alat berat (mekanik) | E23: L.07 | F23: Oh | G23: 0
C24: 8 | D24: Operator alat berat | E24: L.08 | F24: Oh | G24: 0
C25: 9 | D25: Pembantu operator | E25: L.09 | F25: Oh | G25: 0
C26: 10 | D26: Sopir truk | E26: L.10 | F26: Oh | G26: 0
C27: 11 | D27: Kenek truk | E27: L.11 | F27: Oh | G27: 0
C28: 12 | D28: Penjaga malam | E28: L.12 | F28: Oh | G28: 0
C29: 13 | D29: Juru gambar (drafter) | E29: L.13 | F29: Oh | G29: 0
C30: 14 | D30: Design Engineer | E30: L.14 | F30: Oh | G30: 0
... C32: 16 | D32: Lainnya | E32: L.16 | F32: Oh | G32: 0
