Workbook

Sheet Specification
A1: SPECIFICATION & METHOD
A3: Material Type | B3: Product | C3: Parameter | D3: Method | E3: Unit | F3: Spec Min | G3: Spec Max
A4: IM | B4: Cylo | C4: Moisture content | D4: Moisture balance | E4: % | F4: =100-0.2 -> 99.8 | G4: =99.7 -> 99.7
B5: Cylo | C5: Stability/phase separation | D5: Centrifuge (10 min) | E5: - | F5: No separation | G5: No separation
A6: FG | B6: Cylo | C6: pH | D6: pH meter | E6: - | F6: 3 | G6: 7.5
B7: Cylo | C7: Viscosity | D7: Viscometer | E7: cPs | F7: 30 | G7: 50
B8: Cylo | C8: Moisture content | D8: Moisture balance | E8: % | F8: =100-0.1 -> 99.9 | G8: 99.8
B9: Cylo | C9: Total plate count | D9: TPC-ISO 4833-1 | E9: CFU/g | F9: 0 | G9: 1000
B10: Cylo | C10: Mould count | D10: Mould - ISO 21527 | E10: CFU/g | F10: 0 | G10: 100
B11: Cylo | C11: E. Coli | D11: E. coli - ISO 16649-2 | E11: - | F11: Negative | G11: Negative
B12: Cylo | C12: Stability/phase separation | D12: Centrifuge (10 min) | E12: - | F12: No separation | G12: No separation
A13: IM | B13: Cylo Bind | C13: Moisture content | D13: Moisture balance | E13: % | F13: =100-0.2 -> 99.8 | G13: =99.7 -> 99.7
B14: Cylo Bind | C14: Stability/phase separation | D14: Centrifuge (10 min) | E14: - | F14: No separation | G14: No separation
A15: FG | B15: Cylo Bind | C15: pH | D15: pH meter | E15: - | F15: 3 | G15: 7.5
B16: Cylo Bind | C16: Viscosity | D16: Viscometer | E16: cPs | F16: 30 | G16: 50
B17: Cylo Bind | C17: Moisture content | D17: Moisture balance | E17: % | F17: =100-0.2 -> 99.8 | G17: =99.7 -> 99.7
B18: Cylo Bind | C18: Total plate count | D18: TPC-ISO 4833-1 | E18: CFU/g | F18: 0 | G18: 1000
B19: Cylo Bind | C19: Mould count | D19: Mould - ISO 21527 | E19: CFU/g | F19: 0 | G19: 100
B20: Cylo Bind | C20: E. Coli | D20: E. coli - ISO 16649-2 | E20: - | F20: Negative | G20: Negative
B21: Cylo Bind | C21: Stability/phase separation | D21: Centrifuge (10 min) | E21: - | F21: No separation | G21: No separation
A22: FG | B22: Cylo Plus | C22: Appearance | D22: Visual | E22: - | F22: Hazy liquid colorless | G22: Hazy liquid colorless
B23: Cylo Plus | C23: pH | D23: pH meter | E23: - | F23: 4 | G23: 7.5
B24: Cylo Plus | C24: Viscosity | D24: Viscometer | E24: cPs | F24: 40 | G24: 100
B25: Cylo Plus | C25: Density | D25: Hydrometer | E25: g/ml | F25: 0.99 | G25: 1.02
A26: FG | B26: Cylo Plus V | C26: Appearance | D26: Visual | E26: - | F26: Hazy liquid colorless | G26: Hazy liquid colorless
B27: Cylo Plus V | C27: pH | D27: pH meter | E27: - | F27: 4 | G27: 7.5
B28: Cylo Plus V | C28: Viscosity | D28: Viscometer | E28: cPs | F28: 40 | G28: 100
B29: Cylo Plus V | C29: Density | D29: Hydrometer | E29: g/ml | F29: 0.99 | G29: 1.02

Sheet Item Code
A1: List Kode Barang
A2: SKU --> Stock Keeping Unit
A3: UTAMA | B3: Kode
A4: Inventory | B4: I
A5: Non inventory | B5: N
A7: Kategori | B7: Kode
A8: Product Finish Good | B8: FG
A9: Raw Material | B9: RM
A10: Packaging & Repacking | B10: PM
A11: Spare Part | B11: SR
A12: Service Products | B12: SV
A13: Others | B13: OS
A15: Jenis | B15: Kode
A16: Formulasi Liquid | B16: 10
... A25: not applicable | B25: 23
A27: Item Code | B27: Type | C27: Material Name | D27: Function | E27: Supplier | F27: Price (Rp) | G27: Stock | H27: Unit | I27: Status
A28: IRM1020001 | B28: RM | C28: Pellicle | D28: Main component | H28: kg
A29: IRM1022002 | B29: RM | C29: Carboxymethyl cellulose | D29: Thickener | E29: China | H29: kg
A30: IRM1022003 | B30: RM | C30: Carboxymethyl cellulose | D30: Thickener | E30: Nouryon | H30: kg
A31: IRM1022004 | B31: RM | C31: Raw Water | D31: Solvent | E31: - | H31: L
A32: IRM1022005 | B32: RM | C32: Bronopol | D32: Preservative | H32: kg
A33: IRM1022006 | B33: RM | C33: Kaporit | D33: Desinfectant agent | H33: kg
A34: IRM1022007 | B34: RM | C34: Emulan | D34: Surfactant | H34: L
A35: IRM1022008 | B35: RM | C35: Voxanol GA7 | D35: Surfactant | H35: L
A36: IRM1022009 | B36: RM | C36: Sodium bisulfite | D36: Cleaning agent of pellicle | H36: kg
A37: IRM1022010 | B37: RM | C37: Sodium hydroxide | D37: Cleaning agent of pellicle | H37: kg
A38: IPM1223011 | B38: PM | C38: Label sticker karton box C2509 | D38: Packaging material | H38: pcs
A39: IPM1223012 | B39: PM | C39: Label sticker karton box Cylo Bind | D39: Packaging material | H39: pcs
A40: IPM1223013 | B40: PM | C40: Label sticker karton box Cylo Plus | D40: Packaging material | H40: pcs
A41: IPM1223014 | B41: PM | C41: Label sticker Cylo Bind @2.5 gal (sisi depan) | D41: Packaging material | H41: pcs
A42: IPM1223015 | B42: PM | C42: Label sticker Cylo Bind @2.5 gal (sisi belakang) | D42: Packaging material | H42: pcs
A43: IPM1223016 | B43: PM | C43: Label sticker C2509 @100 ml, botol PE | D43: Packaging material | H43: pcs
... A68: IPM1223041 | B68: PM | C68: Cap Jerrycan PE white @2.5 gal | D68: Packaging material | H68: pcs
A69: IPM1223042 | B69: PM | C69: Drum PE Biru @ 200 ltr | D69: Packaging material
A70: IPM1223043 | B70: PM | C70: Seal drum PE biru @ 200 ltr | D70: Packaging material
A71: IPM1223044 | B71: PM | C71: Carboard box white (360×250×324 mm) | D71: Packaging material | H71: pcs
A72: IPM1223045 | B72: PM | C72: Clear packaging tape | D72: Packaging material | H72: pcs
A73: IPM1223046 | B73: PM | C73: Pallet (1100×1100 mm) | D73: Packaging material | H73: pcs
A74: IFG1021047 | B74: FG | C74: C2509 @ 100 ml | D74: Finish Good
A75: IFG1021048 | B75: FG | C75: C2509 @500 ml | D75: Finish Good
...

Sheet BOM Detail Cylo 
A1: Bill of Materials Cylo @200 ltr
A4: BOM ID | B4: Version | C4: RM ID | D4: Material Name | E4: Function | F4: Unit | G4: Quantity | H4: Use tolerance | I4: %Tolerance | J4: Tolerance value | K4: Remark
A5: ='Item Code'!A78 -> IFG1021051 | B5: V1 | C5: ='Item Code'!A28 -> IRM1020001 | D5: ='Item Code'!C28 -> Pellicle | E5: ='Item Code'!D28 -> Main component | F5: kg | G5: 100.7 | H5: 0 | I5: 0 | J5: 0 | K5: 0
C6: ='Item Code'!A29 -> IRM1022002 | D6: ='Item Code'!C29 -> Carboxymethyl cellulose | E6: ='Item Code'!D29 -> Thickener | F6: kg | G6: 0.81 | H6: 0 | I6: 0 | J6: 0 | K6: 0
C7: ='Item Code'!A31 -> IRM1022004 | D7: Raw Water | E7: Solvent | F7: kg | G7: 902.62 | H7: 0 | I7: 0 | J7: 0 | K7: 0
C8: ='Item Code'!A32 -> IRM1022005 | D8: ='Item Code'!C32 -> Bronopol | E8: ='Item Code'!D32 -> Preservative | F8: kg | G8: 0.81 | H8: 0 | I8: 0 | J8: 0 | K8: 0
C9: ='Item Code'!A33 -> IRM1022006 | D9: ='Item Code'!C33 -> Kaporit | E9: ='Item Code'!D33 -> Desinfectant agent | F9: kg | G9: 0.05 | H9: 0 | I9: 0 | J9: 0 | K9: 0
C10: ='Item Code'!A36 -> IRM1022009 | D10: ='Item Code'!C36 -> Sodium bisulfite | E10: ='Item Code'!D36 -> Cleaning agent of pellicle | F10: kg | G10: 2.01 | H10: 0 | I10: 0 | J10: 0 | K10: 0
C11: ='Item Code'!A47 -> IPM1223020 | D11: ='Item Code'!C47 -> Label sticker C2509 @ 200 ltr, drum | E11: ='Item Code'!D47 -> Packaging material | F11: pcs | G11: 1 | H11: 0 | I11: 0 | J11: 0 | K11: 0
C12: ='Item Code'!A69 -> IPM1223042 | D12: ='Item Code'!C69 -> Drum PE Biru @ 200 ltr | E12: ='Item Code'!D69 -> Packaging material | F12: pcs | G12: 1 | H12: 0 | I12: 0 | J12: 0 | K12: 0
C13: ='Item Code'!A70 -> IPM1223043 | D13: ='Item Code'!C70 -> Seal drum PE biru @ 200 ltr | E13: ='Item Code'!D70 -> Packaging material | F13: pcs | G13: 1 | H13: 0 | I13: 0 | J13: 0 | K13: 0
C14: ='Item Code'!A73 -> IPM1223046 | D14: ='Item Code'!C73 -> Pallet (1100×1100 mm) | E14: ='Item Code'!D73 -> Packaging material | F14: pcs | G14: 1 | H14: 0 | I14: 0 | J14: 0 | K14: 0

Sheet BOM Detail Cylo Bind
A1: Bill of Materials Cylo Bind @2.5 gal
A4: BOM ID | B4: Version | C4: RM ID | D4: Material Name | E4: Function | F4: Unit | G4: Quantity | H4: Use tolerance | I4: %Tolerance | J4: Tolerance value | K4: Remark
A5: ='Item Code'!A83 -> IFG1021056 | B5: V1 | C5: ='Item Code'!A28 -> IRM1020001 | D5: ='Item Code'!C28 -> Pellicle | E5: ='Item Code'!D28 -> Main component | F5: kg | G5: 201.4 | H5: 0 | I5: 0 | J5: 0 | K5: 0
C6: ='Item Code'!A29 -> IRM1022002 | D6: ='Item Code'!C29 -> Carboxymethyl cellulose | E6: ='Item Code'!D29 -> Thickener | F6: kg | G6: 0.81 | H6: 0 | I6: 0 | J6: 0 | K6: 0
C7: ='Item Code'!A31 -> IRM1022004 | D7: Raw Water | E7: Solvent | F7: kg | G7: 801.92 | H7: 0 | I7: 0 | J7: 0 | K7: 0
C8: ='Item Code'!A32 -> IRM1022005 | D8: ='Item Code'!C32 -> Bronopol | E8: ='Item Code'!D32 -> Preservative | F8: kg | G8: 0.81 | H8: 0 | I8: 0 | J8: 0 | K8: 0
C9: ='Item Code'!A33 -> IRM1022006 | D9: ='Item Code'!C33 -> Kaporit | E9: ='Item Code'!D33 -> Desinfectant agent | F9: kg | G9: 0.05 | H9: 0 | I9: 0 | J9: 0 | K9: 0
C10: ='Item Code'!A36 -> IRM1022009 | D10: ='Item Code'!C36 -> Sodium bisulfite | E10: ='Item Code'!D36 -> Cleaning agent of pellicle | F10: kg | G10: 2.01 | H10: 0 | I10: 0 | J10: 0 | K10: 0
C11: ='Item Code'!A41 -> IPM1223014 | D11: ='Item Code'!C41 -> Label sticker Cylo Bind @2.5 gal (sisi depan) | E11: ='Item Code'!D41 -> Packaging material | F11: pcs | G11: 1 | H11: 0 | I11: 0 | J11: 0 | K11: 0
C12: ='Item Code'!A42 -> IPM1223015 | D12: ='Item Code'!C42 -> Label sticker Cylo Bind @2.5 gal (sisi belakang) | E12: ='Item Code'!D42 -> Packaging material | F12: pcs | G12: 1 | H12: 0 | I12: 0 | J12: 0 | K12: 0
C13: ='Item Code'!A67 -> IPM1223040 | D13: ='Item Code'!C67 -> Jerrycan PE white @2.5 gal | E13: ='Item Code'!D67 -> Packaging material | F13: pcs | G13: 1 | H13: 0 | I13: 0 | J13: 0 | K13: 0
C14: ='Item Code'!A68 -> IPM1223041 | D14: ='Item Code'!C68 -> Cap Jerrycan PE white @2.5 gal | E14: ='Item Code'!D68 -> Packaging material | F14: pcs | G14: 1 | H14: 0 | I14: 0 | J14: 0 | K14: 0
C15: ='Item Code'!A71 -> IPM1223044 | D15: ='Item Code'!C71 -> Carboard box white (360×250×324 mm) | E15: ='Item Code'!D71 -> Packaging material | F15: pcs | G15: 1 | H15: 0 | I15: 0 | J15: 0 | K15: 0
C16: ='Item Code'!A72 -> IPM1223045 | D16: ='Item Code'!C72 -> Clear packaging tape | E16: ='Item Code'!D72 -> Packaging material | F16: pcs | G16: 1 | H16: 0 | I16: 0 | J16: 0 | K16: 0
C17: ='Item Code'!A73 -> IPM1223046 | D17: ='Item Code'!C73 -> Pallet (1100×1100 mm) | E17: ='Item Code'!D73 -> Packaging material | F17: pcs | G17: 1 | H17: 0 | I17: 0 | J17: 0 | K17: 0

Sheet BOM Detail Cylo Plus
A1: Bill of Materials Cylo Plus @200 ltr
A4: BOM ID | B4: Version | C4: RM ID | D4: Material Name | E4: Function | F4: Unit | G4: Quantity | H4: Use tolerance | I4: %Tolerance | J4: Tolerance value | K4: Remark
A5: ='Item Code'!A89 -> IFG1021062 | B5: V1 | C5: ='Item Code'!A28 -> IRM1020001 | D5: ='Item Code'!C28 -> Pellicle | E5: ='Item Code'!D28 -> Main component | F5: kg | G5: 100.7 | H5: 0 | I5: 0 | J5: 0 | K5: 0
C6: ='Item Code'!A29 -> IRM1022002 | D6: ='Item Code'!C29 -> Carboxymethyl cellulose | E6: ='Item Code'!D29 -> Thickener | F6: kg | G6: 0.81 | H6: 0 | I6: 0 | J6: 0 | K6: 0
C7: ='Item Code'!A31 -> IRM1022004 | D7: Raw Water | E7: Solvent | F7: kg | G7: 902.62 | H7: 0 | I7: 0 | J7: 0 | K7: 0
C8: ='Item Code'!A32 -> IRM1022005 | D8: ='Item Code'!C32 -> Bronopol | E8: ='Item Code'!D32 -> Preservative | F8: kg | G8: 0.81 | H8: 0 | I8: 0 | J8: 0 | K8: 0
C9: ='Item Code'!A33 -> IRM1022006 | D9: ='Item Code'!C33 -> Kaporit | E9: ='Item Code'!D33 -> Desinfectant agent | F9: kg | G9: 0.05 | H9: 0 | I9: 0 | J9: 0 | K9: 0
C10: ='Item Code'!A36 -> IRM1022009 | D10: ='Item Code'!C36 -> Sodium bisulfite | E10: ='Item Code'!D36 -> Cleaning agent of pellicle | F10: kg | G10: 2.01 | H10: 0 | I10: 0 | J10: 0 | K10: 0
C11: ='Item Code'!A34 -> IRM1022007 | D11: ='Item Code'!C34 -> Emulan | E11: ='Item Code'!D34 -> Surfactant | F11: L | G11: =1007/3 -> 335.66667 | H11: 0 | I11: 0 | J11: 0 | K11: 0
C12: ='Item Code'!A57 -> IPM1223030 | D12: ='Item Code'!C57 -> Label sticker Cylo plus @ 200 ltr, drum | E12: ='Item Code'!D57 -> Packaging material | F12: pcs | G12: 1 | H12: 0 | I12: 0 | J12: 0 | K12: 0
C13: ='Item Code'!A69 -> IPM1223042 | D13: ='Item Code'!C69 -> Drum PE Biru @ 200 ltr | E13: ='Item Code'!D69 -> Packaging material | F13: pcs | G13: 1 | H13: 0 | I13: 0 | J13: 0 | K13: 0
C14: ='Item Code'!A70 -> IPM1223043 | D14: ='Item Code'!C70 -> Seal drum PE biru @ 200 ltr | E14: ='Item Code'!D70 -> Packaging material | F14: pcs | G14: 1 | H14: 0 | I14: 0 | J14: 0 | K14: 0
C15: ='Item Code'!A73 -> IPM1223046 | D15: ='Item Code'!C73 -> Pallet (1100×1100 mm) | E15: ='Item Code'!D73 -> Packaging material | F15: pcs | G15: 1 | H15: 0 | I15: 0 | J15: 0 | K15: 0

Sheet Formulation
A1: RESEARCH MANAGEMENT SYSTEM
A4: Formula ID | B4: Status | C4: User & Departement | D4: Researcher | E4: Input Date | F4: Research | J4: Formulation | K4: Pesticide | L4: Active Ingredient | M4: Note | N4: Date | Q4: Supporting Data
F5: Background | G5: Purpose | H5: Category | I5: Description | N5: Start | O5: End | P5: Closed | Q5: Report | R5: Remark
A6: F-2601001 | B6: Done | C6: Production | D6: Fera | H6: Rework Production
A7: f-2601002 | B7: Draft | C7: Product Development | H7: Registration
A8: F-2602001 | B8: Master Schedule | C8: Production | H8: Improvement
A9: F-2602002 | B9: Master Schedule | C9: PPIC | H9: Vendor Qualification
A10: F-2602003 | B10: Master Schedule | C10: Product Development | H10: Sample Preparation
A11: F-2603001 | B11: Approved | C11: Production | H11: New Development
A12: F-2602002 | B12: Approved | C12: PPIC | H12: Bill of Materials
A13: F-2604001 | B13: Researcher | C13: R&D | H13: Specification
A14: F-2604002 | B14: Researcher | C14: R&D | H14: New Development

Sheet Sample Management
A1: SAMPLE MANAGEMENT
A3: No | B3: Register Sample | I3: Lab Test Queue | K3: QC Status
B4: Sample ID | C4: Product | D4: Batch | E4: Parameter request | F4: Requestor | G4: Department | H4: Priority | I4: Data Received | J4: Due Date
A5: 1 | B5: SMP-001 | C5: Cylo | D5: 1 | E5: pH, Viscosity | G5: Production | H5: High | K5: Pending QC
A6: 2 | B6: SMP-002 | C6: Cylo | D6: 2 | E6: pH, Viscosity, Microbiology parameter | G6: Customer | H6: Normal | K6: In Testing
A7: 3 | B7: SMP-003 | C7: Cylo Plus | D7: 1 | E7: pH, Viscosity, density | G7: QA/QC | H7: High | K7: Approved
A8: 4 | B8: SMP-004 | C8: Cylo Plus | D8: 2 | E8: pH, Viscosity, density | F8: Fera | G8: R&D | H8: Normal | K8: Rejected
A9: 5 | B9: SMP-005 | C9: Cylo | D9: 3 | E9: Microbiology parameter | G9: Warehouse | H9: Normal | K9: Approved

Sheet Lab Analysis
A1: LAB ANALYSIS
A3: Sample ID | B3: Product | C3: Parameter | D3: Method | E3: Result | F3: Unit | G3: Analyst Name | H3: Test date | I3: Spec Min | J3: Spec Max | K3: Status | L3: Remarks
A4: =[1]Samples!B5 -> SMP-001 | B4: =_xlfn.XLOOKUP([1]Samples!B5,[1]Samples!A:A,[1]Samples!B:B,"") | D4: =_xlfn.XLOOKUP([1]Specifications!G4,[1]Specifications!G:G,[1]Specifications!C:C,"") -> Visual | F4: =_xlfn.XLOOKUP([1]Specifications!G4,[1]Specifications!G:G,[1]Specifications!D:D,"") -> - | I4: =_xlfn.XLOOKUP([1]Specifications!G4,[1]Specifications!G:G,[1]Specifications!E:E,"") -> Hazy liquid colorless | J4: =_xlfn.XLOOKUP([1]Specifications!G4,[1]Specifications!G:G,[1]Specifications!F:F,"") -> Hazy liquid colorless | K4: PASS
A5: =[1]Samples!B6 -> SMP-002 | B5: =_xlfn.XLOOKUP(A5,[1]Samples!A:A,[1]Samples!B:B,"") | K5: PASS
A6: =[1]Samples!B7 -> SMP-003 | B6: =_xlfn.XLOOKUP(A6,[1]Samples!A:A,[1]Samples!B:B,"") | K6: FAIL
A7: =[1]Samples!B8 -> SMP-004 | B7: =_xlfn.XLOOKUP(A7,[1]Samples!A:A,[1]Samples!B:B,"") | K7: FAIL
A8: =[1]Samples!B9 -> SMP-005 | B8: =_xlfn.XLOOKUP(A8,[1]Samples!A:A,[1]Samples!B:B,"") | K8: PASS
